Workbook

Sheet Analysis
B1: Statistical Process Capability & Optimization Tool
B2: Automotive Dimensional Capability Analysis — Single Characteristic | Excel Edition
B4: I. SPECIFICATIONS | F4: EFFECTIVE DATA (auto-selected by mode) | I4: V. PROBABILITY & DEFECTS
B5: Measurement Name | C5: Diameter A | F5: Worksheet x̄ | G5: =Data!G6 | I5: P(x > USL) | J5: =IF(G10=0,IF(G9>C8,1,0),1-NORM.DIST(C8,G9,G10,TRUE))
B6: Target Mean (Tₘ) | C6: 10 | F6: Worksheet σ | G6: =Data!G7 | I6: P(x < LSL) | J6: =IF(G10=0,IF(G9<C7,1,0),NORM.DIST(C7,G9,G10,TRUE))
B7: Lower Spec Limit (LSL) | C7: 9.9 | F7: Worksheet n | G7: =Data!G5 | I7: P(x < Tₘ) | J7: =IF(G10=0,IF(G9<C6,1,0),NORM.DIST(C6,G9,G10,TRUE))
B8: Upper Spec Limit (USL) | C8: 10.1 | F8: ▼ Active values used in calculations: | I8: PPM Above USL | J8: =J5*1000000
B9: II. DATA & GOALS | F9: x̄ (ACTIVE) | G9: =IF(C10="Use Data Worksheet",G5,C12) | I9: PPM Below LSL | J9: =J6*1000000
B10: Data Input Mode | C10: Enter Manually | F10: σ (ACTIVE) | G10: =IF(C10="Use Data Worksheet",G6,C13) | I10: Total PPM | J10: =J8+J9
B11: ▼ Manual inputs (used when Mode = Enter Manually) | F11: n (ACTIVE) | G11: =IF(C10="Use Data Worksheet",G7,C14)
B12: x̄ (Measured Mean) | C12: 10 | I12: VI. HYPOTHESIS TEST (μ vs Tₘ)
B13: σ (Standard Deviation) | C13: 0.015 | F13: IV. CALCULATED RESULTS | I13: Standard Error (SE) | J13: =IF(G10=0,0,G10/SQRT(G11))
B14: n (Sample Size) | C14: 30 | F14: Tolerance (T = USL − LSL) | G14: =C8-C7 | I14: Z-statistic | J14: =IF(J13=0,IF(G9=C6,0,999),(G9-C6)/J13)
B15: III. TARGETS & SETTINGS | F15: 6σ Spread | G15: =6*G10 | I15: p-value | J15: =IF(C19="Two-Sided",2*(1-NORM.S.DIST(ABS(J14),TRUE)),IF(C19="Upper-Sided",1-NORM.S.DIST(J14,TRUE),NORM.S.DIST(J14,TRUE)))
B16: Target Capability Index | C16: 1.67 | F16: 8σ Spread | G16: =8*G10 | I16: Alpha (α) | J16: =1-C17/100
B17: Confidence Level (%) | C17: 95 | F17: Cp (Potential Capability) | G17: =IF(G10=0,"∞",(C8-C7)/(6*G10)) | I17: Decision | J17: =IF(J15<J16,"❌ Reject H₀ — Mean shifted","✅ Fail to Reject H₀ — On target")
B18: Decimal Places | C18: 3 | F18: Cpk (Actual Capability) | G18: =IF(G10=0,"∞",MIN((C8-G9)/(3*G10),(G9-C7)/(3*G10))) | I18: CI Lower Bound | J18: =G9-NORM.S.INV(1-J16/2)*J13
B19: Hypothesis Type | C19: Two-Sided | F19: Required Shift (Δ = Tₘ − x̄) | G19: =C6-G9 | I19: CI Upper Bound | J19: =G9+NORM.S.INV(1-J16/2)*J13
F20: Shift Direction | G20: =IF(C6-G9=0,"✅ Centered",IF(C6-G9>0,"⬆ Shift UP","⬇ Shift DOWN"))
F21: Required Tolerance (for target) | G21: =IF(G10=0,0,C16*6*G10) | I21: VII. ASSESSMENT SUMMARY
F22: x̄ − 3σ | G22: =G9-3*G10 | I22: 1. Centering | J22: =IF(G10=0,IF(C6-G9=0,"✅ Perfectly centered (σ=0)","⚠ σ=0 but shift of "&TEXT(C6-G9,"0.000")&" needed"),IF(ABS(C6-G9)<G10*0.05,"✅ Well-centered","⚠ Off-target by "&TEXT(C6-G9,"0.000")))
F23: x̄ + 3σ | G23: =G9+3*G10 | I23: 2. Capability | J23: =IF(G10=0,"✅ Perfect (σ=0, index=∞)",IF(G18>=C16,"✅ Capable: Cpk "&TEXT(G18,"0.000")&" ≥ "&TEXT(C16,"0.00"),IF(G18>=1,"⚠ Marginal: Cpk "&TEXT(G18,"0.000"),"❌ Not Capable: Cpk "&TEXT(G18,"0.000"))))
F24: x̄ − 4σ | G24: =G9-4*G10 | I24: 3. Robustness | J24: =IF(G10=0,"✅ Robust (σ=0)",IF(AND(C7<G24,C8>G25),"✅ Robust: ±4σ within specs",IF(AND(C7<G22,C8>G23),"⚠ Marginal: ±3σ OK, ±4σ NOT","❌ Not Robust: ±3σ breaches specs")))
F25: x̄ + 4σ | G25: =G9+4*G10 | I25: 4. Tolerance | J25: =IF(G10=0,"✅ Adequate (σ=0)",IF(G21<=G14,"✅ Adequate: Tol "&TEXT(G14,"0.000")&" ≥ required "&TEXT(G21,"0.000"),"❌ Inadequate: needs "&TEXT(G21,"0.000")&" but only "&TEXT(G14,"0.000")))
I26: 5. Hypothesis | J26: =J17
B28: =IF(OR(G18<1,G21>G14),"❌ ACTION REQUIRED — Process not capable",IF(OR(G18<C16,ABS(C6-G9)>G10*0.05,J15<J16),"⚠ MARGINAL — Review recommendations","✅ PROCESS HEALTH: GOOD"))
B30: RECOMMENDATIONS
B31: =IF(ABS(C6-G9)>G10*0.05,"• Adjust process mean by "&TEXT(C6-G9,"0.000")&" to center on target.","")&IF(G18<C16,CHAR(10)&"• Reduce variation (σ) to meet capability target of "&TEXT(C16,"0.00")&".","")&IF(G21>G14,CHAR(10)&"• Widen tolerance or reduce σ. Required: "&TEXT(G21,"0.000")&", current: "&TEXT(G14,"0.000")&".","")&IF(J15<J16,CHAR(10)&"• Hypothesis test shows significant mean shift (p="&TEXT(J15,"0.0000")&" < α="&TEXT(J16,"0.00")&").","")&IF(AND(G18>=C16,ABS(C6-G9)<=G10*0.05,G21<=G14,J15>=J16),"• Process meets all criteria. Monitor for stability.","")

Sheet Data
B1: Data Worksheet — Part-by-Part Entry
B2: Enter DMC and measured Value below (max 1000 parts). Statistics auto-link to Analysis sheet.
B3: =Analysis!C5&" | Tₘ="&TEXT(Analysis!C6,"0.000")&" | LSL="&TEXT(Analysis!C7,"0.000")&" | USL="&TEXT(Analysis!C8,"0.000") | F3: =G5&" of 1000 rows used ("&TEXT(G5/1000,"0%")&" capacity)"
B4: # | C4: DMC / Serial Number | D4: Value | F4: AUTO-CALCULATED STATISTICS
B5: 1 | C5: DMC-2024-001 | D5: 10.005 | F5: Count (n) | G5: =COUNTA(D5:D1004)
B6: 2 | C6: DMC-2024-002 | D6: 9.998 | F6: Mean (x̄) | G6: =IF(G5>=2,AVERAGE(D5:D1004),"")
B7: 3 | C7: DMC-2024-003 | D7: 10.012 | F7: Std Dev (σ) | G7: =IF(G5>=2,STDEV.S(D5:D1004),"")
B8: 4 | C8: DMC-2024-004 | D8: 9.985 | F8: Min | G8: =IF(G5>=1,MIN(D5:D1004),"")
B9: 5 | C9: DMC-2024-005 | D9: 10.008 | F9: Max | G9: =IF(G5>=1,MAX(D5:D1004),"")
B10: 6 | C10: DMC-2024-006 | D10: 9.992 | F10: Range | G10: =IF(G5>=2,G9-G8,"")
B11: 7 | C11: DMC-2024-007 | D11: 10.015 | F11: Median | G11: =IF(G5>=1,MEDIAN(D5:D1004),"")
B12: 8 | C12: DMC-2024-008 | D12: 10.001 | F12: Q1 (25th %ile) | G12: =IF(G5>=4,PERCENTILE(D5:D1004,0.25),"")
B13: 9 | C13: DMC-2024-009 | D13: 9.99 | F13: Q3 (75th %ile) | G13: =IF(G5>=4,PERCENTILE(D5:D1004,0.75),"")
B14: 10 | C14: DMC-2024-010 | D14: 10.01 | F14: IQR | G14: =IF(G5>=4,G13-G12,"")
B15: 11 | F15: Skewness | G15: =IF(G5>=3,SKEW(D5:D1004),"")
B16: 12 | F16: Kurtosis | G16: =IF(G5>=4,KURT(D5:D1004),"")
B17: 13
B18: 14 | F18: =IF(G5>=2,"✅ "&G5&" of 1000 data points ready. Analysis auto-linked.","⚠ Need ≥2 data points (1000 max allowed).")
B19: 15
B20: 16 | F20: QUICK PREVIEW (from worksheet data)
B21: 17 | F21: Cp (preview) | G21: =IF(G7=""," — ", IF(G7=0,"∞",(Analysis!C8-Analysis!C7)/(6*G7)))
B22: 18 | F22: Cpk (preview) | G22: =IF(G7=""," — ", IF(G7=0,"∞",MIN((Analysis!C8-G6)/(3*G7),(G6-Analysis!C7)/(3*G7))))
B23: 19
B24: 20 | F24: 💡 10 sample data points pre-filled as template. Replace with your actual measurements.
B25: 21
B26: 22
B27: 23
B28: 24
B29: 25
B30: 26
B31: 27
B32: 28
B33: 29
B34: 30
B35: 31
B36: 32
... B1004: 1000

Sheet Charts
B1: Visualization — Process Capability & Control Charts
H2: Show Points: | I2: 50 | J2: =IF(I2="All",1000,I2)
B3: Normal Distribution Curve Data | H3: I-MR Control Chart Data (filtered by Show Points)
B4: z | C4: x Value | D4: Current PDF | E4: Centered PDF | H4: # | I4: Value | J4: MR | K4: x̄ (CL) | L4: UCL | M4: LCL
B5: -4 | C5: =Analysis!G9+B5*Analysis!G10 | D5: =IF(Analysis!G10>0,(1/(Analysis!G10*SQRT(2*PI())))*EXP(-0.5*B5^2),0) | E5: =IF(Analysis!G10>0,(1/(Analysis!G10*SQRT(2*PI())))*EXP(-0.5*((C5-Analysis!C6)/Analysis!G10)^2),0) | H5: 1 | I5: =IF(OR(1>$J$2,Data!D5=""),NA(),Data!D5) | J5: =IF(1>$J$2,NA(),NA()) | K5: =IF(OR(1>$J$2,Data!G5<2),NA(),Data!G6) | L5: =IF(OR(1>$J$2,Data!G5<2),NA(),Data!G6+2.66*AVERAGE(J6:J104)) | M5: =IF(OR(1>$J$2,Data!G5<2),NA(),Data!G6-2.66*AVERAGE(J6:J104))
B6: -3.75 | C6: =Analysis!G9+B6*Analysis!G10 | D6: =IF(Analysis!G10>0,(1/(Analysis!G10*SQRT(2*PI())))*EXP(-0.5*B6^2),0) | E6: =IF(Analysis!G10>0,(1/(Analysis!G10*SQRT(2*PI())))*EXP(-0.5*((C6-Analysis!C6)/Analysis!G10)^2),0) | H6: 2 | I6: =IF(OR(2>$J$2,Data!D6=""),NA(),Data!D6) | J6: =IF(OR(2>$J$2,Data!D6="",Data!D5=""),NA(),ABS(Data!D6-Data!D5)) | K6: =IF(OR(2>$J$2,Data!G5<2),NA(),Data!G6) | L6: =IF(OR(2>$J$2,Data!G5<2),NA(),Data!G6+2.66*AVERAGE(J6:J104)) | M6: =IF(OR(2>$J$2,Data!G5<2),NA(),Data!G6-2.66*AVERAGE(J6:J104))
B7: -3.5 | C7: =Analysis!G9+B7*Analysis!G10 | D7: =IF(Analysis!G10>0,(1/(Analysis!G10*SQRT(2*PI())))*EXP(-0.5*B7^2),0) | E7: =IF(Analysis!G10>0,(1/(Analysis!G10*SQRT(2*PI())))*EXP(-0.5*((C7-Analysis!C6)/Analysis!G10)^2),0) | H7: 3 | I7: =IF(OR(3>$J$2,Data!D7=""),NA(),Data!D7) | J7: =IF(OR(3>$J$2,Data!D7="",Data!D6=""),NA(),ABS(Data!D7-Data!D6)) | K7: =IF(OR(3>$J$2,Data!G5<2),NA(),Data!G6) | L7: =IF(OR(3>$J$2,Data!G5<2),NA(),Data!G6+2.66*AVERAGE(J6:J104)) | M7: =IF(OR(3>$J$2,Data!G5<2),NA(),Data!G6-2.66*AVERAGE(J6:J104))
B8: -3.25 | C8: =Analysis!G9+B8*Analysis!G10 | D8: =IF(Analysis!G10>0,(1/(Analysis!G10*SQRT(2*PI())))*EXP(-0.5*B8^2),0) | E8: =IF(Analysis!G10>0,(1/(Analysis!G10*SQRT(2*PI())))*EXP(-0.5*((C8-Analysis!C6)/Analysis!G10)^2),0) | H8: 4 | I8: =IF(OR(4>$J$2,Data!D8=""),NA(),Data!D8) | J8: =IF(OR(4>$J$2,Data!D8="",Data!D7=""),NA(),ABS(Data!D8-Data!D7)) | K8: =IF(OR(4>$J$2,Data!G5<2),NA(),Data!G6) | L8: =IF(OR(4>$J$2,Data!G5<2),NA(),Data!G6+2.66*AVERAGE(J6:J104)) | M8: =IF(OR(4>$J$2,Data!G5<2),NA(),Data!G6-2.66*AVERAGE(J6:J104))
B9: -3 | C9: =Analysis!G9+B9*Analysis!G10 | D9: =IF(Analysis!G10>0,(1/(Analysis!G10*SQRT(2*PI())))*EXP(-0.5*B9^2),0) | E9: =IF(Analysis!G10>0,(1/(Analysis!G10*SQRT(2*PI())))*EXP(-0.5*((C9-Analysis!C6)/Analysis!G10)^2),0) | H9: 5 | I9: =IF(OR(5>$J$2,Data!D9=""),NA(),Data!D9) | J9: =IF(OR(5>$J$2,Data!D9="",Data!D8=""),NA(),ABS(Data!D9-Data!D8)) | K9: =IF(OR(5>$J$2,Data!G5<2),NA(),Data!G6) | L9: =IF(OR(5>$J$2,Data!G5<2),NA(),Data!G6+2.66*AVERAGE(J6:J104)) | M9: =IF(OR(5>$J$2,Data!G5<2),NA(),Data!G6-2.66*AVERAGE(J6:J104))
B10: -2.75 | C10: =Analysis!G9+B10*Analysis!G10 | D10: =IF(Analysis!G10>0,(1/(Analysis!G10*SQRT(2*PI())))*EXP(-0.5*B10^2),0) | E10: =IF(Analysis!G10>0,(1/(Analysis!G10*SQRT(2*PI())))*EXP(-0.5*((C10-Analysis!C6)/Analysis!G10)^2),0) | H10: 6 | I10: =IF(OR(6>$J$2,Data!D10=""),NA(),Data!D10) | J10: =IF(OR(6>$J$2,Data!D10="",Data!D9=""),NA(),ABS(Data!D10-Data!D9)) | K10: =IF(OR(6>$J$2,Data!G5<2),NA(),Data!G6) | L10: =IF(OR(6>$J$2,Data!G5<2),NA(),Data!G6+2.66*AVERAGE(J6:J104)) | M10: =IF(OR(6>$J$2,Data!G5<2),NA(),Data!G6-2.66*AVERAGE(J6:J104))
B11: -2.5 | C11: =Analysis!G9+B11*Analysis!G10 | D11: =IF(Analysis!G10>0,(1/(Analysis!G10*SQRT(2*PI())))*EXP(-0.5*B11^2),0) | E11: =IF(Analysis!G10>0,(1/(Analysis!G10*SQRT(2*PI())))*EXP(-0.5*((C11-Analysis!C6)/Analysis!G10)^2),0) | H11: 7 | I11: =IF(OR(7>$J$2,Data!D11=""),NA(),Data!D11) | J11: =IF(OR(7>$J$2,Data!D11="",Data!D10=""),NA(),ABS(Data!D11-Data!D10)) | K11: =IF(OR(7>$J$2,Data!G5<2),NA(),Data!G6) | L11: =IF(OR(7>$J$2,Data!G5<2),NA(),Data!G6+2.66*AVERAGE(J6:J104)) | M11: =IF(OR(7>$J$2,Data!G5<2),NA(),Data!G6-2.66*AVERAGE(J6:J104))
B12: -2.25 | C12: =Analysis!G9+B12*Analysis!G10 | D12: =IF(Analysis!G10>0,(1/(Analysis!G10*SQRT(2*PI())))*EXP(-0.5*B12^2),0) | E12: =IF(Analysis!G10>0,(1/(Analysis!G10*SQRT(2*PI())))*EXP(-0.5*((C12-Analysis!C6)/Analysis!G10)^2),0) | H12: 8 | I12: =IF(OR(8>$J$2,Data!D12=""),NA(),Data!D12) | J12: =IF(OR(8>$J$2,Data!D12="",Data!D11=""),NA(),ABS(Data!D12-Data!D11)) | K12: =IF(OR(8>$J$2,Data!G5<2),NA(),Data!G6) | L12: =IF(OR(8>$J$2,Data!G5<2),NA(),Data!G6+2.66*AVERAGE(J6:J104)) | M12: =IF(OR(8>$J$2,Data!G5<2),NA(),Data!G6-2.66*AVERAGE(J6:J104))
B13: -2 | C13: =Analysis!G9+B13*Analysis!G10 | D13: =IF(Analysis!G10>0,(1/(Analysis!G10*SQRT(2*PI())))*EXP(-0.5*B13^2),0) | E13: =IF(Analysis!G10>0,(1/(Analysis!G10*SQRT(2*PI())))*EXP(-0.5*((C13-Analysis!C6)/Analysis!G10)^2),0) | H13: 9 | I13: =IF(OR(9>$J$2,Data!D13=""),NA(),Data!D13) | J13: =IF(OR(9>$J$2,Data!D13="",Data!D12=""),NA(),ABS(Data!D13-Data!D12)) | K13: =IF(OR(9>$J$2,Data!G5<2),NA(),Data!G6) | L13: =IF(OR(9>$J$2,Data!G5<2),NA(),Data!G6+2.66*AVERAGE(J6:J104)) | M13: =IF(OR(9>$J$2,Data!G5<2),NA(),Data!G6-2.66*AVERAGE(J6:J104))
B14: -1.75 | C14: =Analysis!G9+B14*Analysis!G10 | D14: =IF(Analysis!G10>0,(1/(Analysis!G10*SQRT(2*PI())))*EXP(-0.5*B14^2),0) | E14: =IF(Analysis!G10>0,(1/(Analysis!G10*SQRT(2*PI())))*EXP(-0.5*((C14-Analysis!C6)/Analysis!G10)^2),0) | H14: 10 | I14: =IF(OR(10>$J$2,Data!D14=""),NA(),Data!D14) | J14: =IF(OR(10>$J$2,Data!D14="",Data!D13=""),NA(),ABS(Data!D14-Data!D13)) | K14: =IF(OR(10>$J$2,Data!G5<2),NA(),Data!G6) | L14: =IF(OR(10>$J$2,Data!G5<2),NA(),Data!G6+2.66*AVERAGE(J6:J104)) | M14: =IF(OR(10>$J$2,Data!G5<2),NA(),Data!G6-2.66*AVERAGE(J6:J104))
B15: -1.5 | C15: =Analysis!G9+B15*Analysis!G10 | D15: =IF(Analysis!G10>0,(1/(Analysis!G10*SQRT(2*PI())))*EXP(-0.5*B15^2),0) | E15: =IF(Analysis!G10>0,(1/(Analysis!G10*SQRT(2*PI())))*EXP(-0.5*((C15-Analysis!C6)/Analysis!G10)^2),0) | H15: 11 | I15: =IF(OR(11>$J$2,Data!D15=""),NA(),Data!D15) | J15: =IF(OR(11>$J$2,Data!D15="",Data!D14=""),NA(),ABS(Data!D15-Data!D14)) | K15: =IF(OR(11>$J$2,Data!G5<2),NA(),Data!G6) | L15: =IF(OR(11>$J$2,Data!G5<2),NA(),Data!G6+2.66*AVERAGE(J6:J104)) | M15: =IF(OR(11>$J$2,Data!G5<2),NA(),Data!G6-2.66*AVERAGE(J6:J104))
B16: -1.25 | C16: =Analysis!G9+B16*Analysis!G10 | D16: =IF(Analysis!G10>0,(1/(Analysis!G10*SQRT(2*PI())))*EXP(-0.5*B16^2),0) | E16: =IF(Analysis!G10>0,(1/(Analysis!G10*SQRT(2*PI())))*EXP(-0.5*((C16-Analysis!C6)/Analysis!G10)^2),0) | H16: 12 | I16: =IF(OR(12>$J$2,Data!D16=""),NA(),Data!D16) | J16: =IF(OR(12>$J$2,Data!D16="",Data!D15=""),NA(),ABS(Data!D16-Data!D15)) | K16: =IF(OR(12>$J$2,Data!G5<2),NA(),Data!G6) | L16: =IF(OR(12>$J$2,Data!G5<2),NA(),Data!G6+2.66*AVERAGE(J6:J104)) | M16: =IF(OR(12>$J$2,Data!G5<2),NA(),Data!G6-2.66*AVERAGE(J6:J104))
B17: -1 | C17: =Analysis!G9+B17*Analysis!G10 | D17: =IF(Analysis!G10>0,(1/(Analysis!G10*SQRT(2*PI())))*EXP(-0.5*B17^2),0) | E17: =IF(Analysis!G10>0,(1/(Analysis!G10*SQRT(2*PI())))*EXP(-0.5*((C17-Analysis!C6)/Analysis!G10)^2),0) | H17: 13 | I17: =IF(OR(13>$J$2,Data!D17=""),NA(),Data!D17) | J17: =IF(OR(13>$J$2,Data!D17="",Data!D16=""),NA(),ABS(Data!D17-Data!D16)) | K17: =IF(OR(13>$J$2,Data!G5<2),NA(),Data!G6) | L17: =IF(OR(13>$J$2,Data!G5<2),NA(),Data!G6+2.66*AVERAGE(J6:J104)) | M17: =IF(OR(13>$J$2,Data!G5<2),NA(),Data!G6-2.66*AVERAGE(J6:J104))
B18: -0.75 | C18: =Analysis!G9+B18*Analysis!G10 | D18: =IF(Analysis!G10>0,(1/(Analysis!G10*SQRT(2*PI())))*EXP(-0.5*B18^2),0) | E18: =IF(Analysis!G10>0,(1/(Analysis!G10*SQRT(2*PI())))*EXP(-0.5*((C18-Analysis!C6)/Analysis!G10)^2),0) | H18: 14 | I18: =IF(OR(14>$J$2,Data!D18=""),NA(),Data!D18) | J18: =IF(OR(14>$J$2,Data!D18="",Data!D17=""),NA(),ABS(Data!D18-Data!D17)) | K18: =IF(OR(14>$J$2,Data!G5<2),NA(),Data!G6) | L18: =IF(OR(14>$J$2,Data!G5<2),NA(),Data!G6+2.66*AVERAGE(J6:J104)) | M18: =IF(OR(14>$J$2,Data!G5<2),NA(),Data!G6-2.66*AVERAGE(J6:J104))
B19: -0.5 | C19: =Analysis!G9+B19*Analysis!G10 | D19: =IF(Analysis!G10>0,(1/(Analysis!G10*SQRT(2*PI())))*EXP(-0.5*B19^2),0) | E19: =IF(Analysis!G10>0,(1/(Analysis!G10*SQRT(2*PI())))*EXP(-0.5*((C19-Analysis!C6)/Analysis!G10)^2),0) | H19: 15 | I19: =IF(OR(15>$J$2,Data!D19=""),NA(),Data!D19) | J19: =IF(OR(15>$J$2,Data!D19="",Data!D18=""),NA(),ABS(Data!D19-Data!D18)) | K19: =IF(OR(15>$J$2,Data!G5<2),NA(),Data!G6) | L19: =IF(OR(15>$J$2,Data!G5<2),NA(),Data!G6+2.66*AVERAGE(J6:J104)) | M19: =IF(OR(15>$J$2,Data!G5<2),NA(),Data!G6-2.66*AVERAGE(J6:J104))
B20: -0.25 | C20: =Analysis!G9+B20*Analysis!G10 | D20: =IF(Analysis!G10>0,(1/(Analysis!G10*SQRT(2*PI())))*EXP(-0.5*B20^2),0) | E20: =IF(Analysis!G10>0,(1/(Analysis!G10*SQRT(2*PI())))*EXP(-0.5*((C20-Analysis!C6)/Analysis!G10)^2),0) | H20: 16 | I20: =IF(OR(16>$J$2,Data!D20=""),NA(),Data!D20) | J20: =IF(OR(16>$J$2,Data!D20="",Data!D19=""),NA(),ABS(Data!D20-Data!D19)) | K20: =IF(OR(16>$J$2,Data!G5<2),NA(),Data!G6) | L20: =IF(OR(16>$J$2,Data!G5<2),NA(),Data!G6+2.66*AVERAGE(J6:J104)) | M20: =IF(OR(16>$J$2,Data!G5<2),NA(),Data!G6-2.66*AVERAGE(J6:J104))
B21: 0 | C21: =Analysis!G9+B21*Analysis!G10 | D21: =IF(Analysis!G10>0,(1/(Analysis!G10*SQRT(2*PI())))*EXP(-0.5*B21^2),0) | E21: =IF(Analysis!G10>0,(1/(Analysis!G10*SQRT(2*PI())))*EXP(-0.5*((C21-Analysis!C6)/Analysis!G10)^2),0) | H21: 17 | I21: =IF(OR(17>$J$2,Data!D21=""),NA(),Data!D21) | J21: =IF(OR(17>$J$2,Data!D21="",Data!D20=""),NA(),ABS(Data!D21-Data!D20)) | K21: =IF(OR(17>$J$2,Data!G5<2),NA(),Data!G6) | L21: =IF(OR(17>$J$2,Data!G5<2),NA(),Data!G6+2.66*AVERAGE(J6:J104)) | M21: =IF(OR(17>$J$2,Data!G5<2),NA(),Data!G6-2.66*AVERAGE(J6:J104))
B22: 0.25 | C22: =Analysis!G9+B22*Analysis!G10 | D22: =IF(Analysis!G10>0,(1/(Analysis!G10*SQRT(2*PI())))*EXP(-0.5*B22^2),0) | E22: =IF(Analysis!G10>0,(1/(Analysis!G10*SQRT(2*PI())))*EXP(-0.5*((C22-Analysis!C6)/Analysis!G10)^2),0) | H22: 18 | I22: =IF(OR(18>$J$2,Data!D22=""),NA(),Data!D22) | J22: =IF(OR(18>$J$2,Data!D22="",Data!D21=""),NA(),ABS(Data!D22-Data!D21)) | K22: =IF(OR(18>$J$2,Data!G5<2),NA(),Data!G6) | L22: =IF(OR(18>$J$2,Data!G5<2),NA(),Data!G6+2.66*AVERAGE(J6:J104)) | M22: =IF(OR(18>$J$2,Data!G5<2),NA(),Data!G6-2.66*AVERAGE(J6:J104))
B23: 0.5 | C23: =Analysis!G9+B23*Analysis!G10 | D23: =IF(Analysis!G10>0,(1/(Analysis!G10*SQRT(2*PI())))*EXP(-0.5*B23^2),0) | E23: =IF(Analysis!G10>0,(1/(Analysis!G10*SQRT(2*PI())))*EXP(-0.5*((C23-Analysis!C6)/Analysis!G10)^2),0) | H23: 19 | I23: =IF(OR(19>$J$2,Data!D23=""),NA(),Data!D23) | J23: =IF(OR(19>$J$2,Data!D23="",Data!D22=""),NA(),ABS(Data!D23-Data!D22)) | K23: =IF(OR(19>$J$2,Data!G5<2),NA(),Data!G6) | L23: =IF(OR(19>$J$2,Data!G5<2),NA(),Data!G6+2.66*AVERAGE(J6:J104)) | M23: =IF(OR(19>$J$2,Data!G5<2),NA(),Data!G6-2.66*AVERAGE(J6:J104))
B24: 0.75 | C24: =Analysis!G9+B24*Analysis!G10 | D24: =IF(Analysis!G10>0,(1/(Analysis!G10*SQRT(2*PI())))*EXP(-0.5*B24^2),0) | E24: =IF(Analysis!G10>0,(1/(Analysis!G10*SQRT(2*PI())))*EXP(-0.5*((C24-Analysis!C6)/Analysis!G10)^2),0) | H24: 20 | I24: =IF(OR(20>$J$2,Data!D24=""),NA(),Data!D24) | J24: =IF(OR(20>$J$2,Data!D24="",Data!D23=""),NA(),ABS(Data!D24-Data!D23)) | K24: =IF(OR(20>$J$2,Data!G5<2),NA(),Data!G6) | L24: =IF(OR(20>$J$2,Data!G5<2),NA(),Data!G6+2.66*AVERAGE(J6:J104)) | M24: =IF(OR(20>$J$2,Data!G5<2),NA(),Data!G6-2.66*AVERAGE(J6:J104))
B25: 1 | C25: =Analysis!G9+B25*Analysis!G10 | D25: =IF(Analysis!G10>0,(1/(Analysis!G10*SQRT(2*PI())))*EXP(-0.5*B25^2),0) | E25: =IF(Analysis!G10>0,(1/(Analysis!G10*SQRT(2*PI())))*EXP(-0.5*((C25-Analysis!C6)/Analysis!G10)^2),0) | H25: 21 | I25: =IF(OR(21>$J$2,Data!D25=""),NA(),Data!D25) | J25: =IF(OR(21>$J$2,Data!D25="",Data!D24=""),NA(),ABS(Data!D25-Data!D24)) | K25: =IF(OR(21>$J$2,Data!G5<2),NA(),Data!G6) | L25: =IF(OR(21>$J$2,Data!G5<2),NA(),Data!G6+2.66*AVERAGE(J6:J104)) | M25: =IF(OR(21>$J$2,Data!G5<2),NA(),Data!G6-2.66*AVERAGE(J6:J104))
B26: 1.25 | C26: =Analysis!G9+B26*Analysis!G10 | D26: =IF(Analysis!G10>0,(1/(Analysis!G10*SQRT(2*PI())))*EXP(-0.5*B26^2),0) | E26: =IF(Analysis!G10>0,(1/(Analysis!G10*SQRT(2*PI())))*EXP(-0.5*((C26-Analysis!C6)/Analysis!G10)^2),0) | H26: 22 | I26: =IF(OR(22>$J$2,Data!D26=""),NA(),Data!D26) | J26: =IF(OR(22>$J$2,Data!D26="",Data!D25=""),NA(),ABS(Data!D26-Data!D25)) | K26: =IF(OR(22>$J$2,Data!G5<2),NA(),Data!G6) | L26: =IF(OR(22>$J$2,Data!G5<2),NA(),Data!G6+2.66*AVERAGE(J6:J104)) | M26: =IF(OR(22>$J$2,Data!G5<2),NA(),Data!G6-2.66*AVERAGE(J6:J104))
B27: 1.5 | C27: =Analysis!G9+B27*Analysis!G10 | D27: =IF(Analysis!G10>0,(1/(Analysis!G10*SQRT(2*PI())))*EXP(-0.5*B27^2),0) | E27: =IF(Analysis!G10>0,(1/(Analysis!G10*SQRT(2*PI())))*EXP(-0.5*((C27-Analysis!C6)/Analysis!G10)^2),0) | H27: 23 | I27: =IF(OR(23>$J$2,Data!D27=""),NA(),Data!D27) | J27: =IF(OR(23>$J$2,Data!D27="",Data!D26=""),NA(),ABS(Data!D27-Data!D26)) | K27: =IF(OR(23>$J$2,Data!G5<2),NA(),Data!G6) | L27: =IF(OR(23>$J$2,Data!G5<2),NA(),Data!G6+2.66*AVERAGE(J6:J104)) | M27: =IF(OR(23>$J$2,Data!G5<2),NA(),Data!G6-2.66*AVERAGE(J6:J104))
B28: 1.75 | C28: =Analysis!G9+B28*Analysis!G10 | D28: =IF(Analysis!G10>0,(1/(Analysis!G10*SQRT(2*PI())))*EXP(-0.5*B28^2),0) | E28: =IF(Analysis!G10>0,(1/(Analysis!G10*SQRT(2*PI())))*EXP(-0.5*((C28-Analysis!C6)/Analysis!G10)^2),0) | H28: 24 | I28: =IF(OR(24>$J$2,Data!D28=""),NA(),Data!D28) | J28: =IF(OR(24>$J$2,Data!D28="",Data!D27=""),NA(),ABS(Data!D28-Data!D27)) | K28: =IF(OR(24>$J$2,Data!G5<2),NA(),Data!G6) | L28: =IF(OR(24>$J$2,Data!G5<2),NA(),Data!G6+2.66*AVERAGE(J6:J104)) | M28: =IF(OR(24>$J$2,Data!G5<2),NA(),Data!G6-2.66*AVERAGE(J6:J104))
B29: 2 | C29: =Analysis!G9+B29*Analysis!G10 | D29: =IF(Analysis!G10>0,(1/(Analysis!G10*SQRT(2*PI())))*EXP(-0.5*B29^2),0) | E29: =IF(Analysis!G10>0,(1/(Analysis!G10*SQRT(2*PI())))*EXP(-0.5*((C29-Analysis!C6)/Analysis!G10)^2),0) | H29: 25 | I29: =IF(OR(25>$J$2,Data!D29=""),NA(),Data!D29) | J29: =IF(OR(25>$J$2,Data!D29="",Data!D28=""),NA(),ABS(Data!D29-Data!D28)) | K29: =IF(OR(25>$J$2,Data!G5<2),NA(),Data!G6) | L29: =IF(OR(25>$J$2,Data!G5<2),NA(),Data!G6+2.66*AVERAGE(J6:J104)) | M29: =IF(OR(25>$J$2,Data!G5<2),NA(),Data!G6-2.66*AVERAGE(J6:J104))
B30: 2.25 | C30: =Analysis!G9+B30*Analysis!G10 | D30: =IF(Analysis!G10>0,(1/(Analysis!G10*SQRT(2*PI())))*EXP(-0.5*B30^2),0) | E30: =IF(Analysis!G10>0,(1/(Analysis!G10*SQRT(2*PI())))*EXP(-0.5*((C30-Analysis!C6)/Analysis!G10)^2),0) | H30: 26 | I30: =IF(OR(26>$J$2,Data!D30=""),NA(),Data!D30) | J30: =IF(OR(26>$J$2,Data!D30="",Data!D29=""),NA(),ABS(Data!D30-Data!D29)) | K30: =IF(OR(26>$J$2,Data!G5<2),NA(),Data!G6) | L30: =IF(OR(26>$J$2,Data!G5<2),NA(),Data!G6+2.66*AVERAGE(J6:J104)) | M30: =IF(OR(26>$J$2,Data!G5<2),NA(),Data!G6-2.66*AVERAGE(J6:J104))
B31: 2.5 | C31: =Analysis!G9+B31*Analysis!G10 | D31: =IF(Analysis!G10>0,(1/(Analysis!G10*SQRT(2*PI())))*EXP(-0.5*B31^2),0) | E31: =IF(Analysis!G10>0,(1/(Analysis!G10*SQRT(2*PI())))*EXP(-0.5*((C31-Analysis!C6)/Analysis!G10)^2),0) | H31: 27 | I31: =IF(OR(27>$J$2,Data!D31=""),NA(),Data!D31) | J31: =IF(OR(27>$J$2,Data!D31="",Data!D30=""),NA(),ABS(Data!D31-Data!D30)) | K31: =IF(OR(27>$J$2,Data!G5<2),NA(),Data!G6) | L31: =IF(OR(27>$J$2,Data!G5<2),NA(),Data!G6+2.66*AVERAGE(J6:J104)) | M31: =IF(OR(27>$J$2,Data!G5<2),NA(),Data!G6-2.66*AVERAGE(J6:J104))
B32: 2.75 | C32: =Analysis!G9+B32*Analysis!G10 | D32: =IF(Analysis!G10>0,(1/(Analysis!G10*SQRT(2*PI())))*EXP(-0.5*B32^2),0) | E32: =IF(Analysis!G10>0,(1/(Analysis!G10*SQRT(2*PI())))*EXP(-0.5*((C32-Analysis!C6)/Analysis!G10)^2),0) | H32: 28 | I32: =IF(OR(28>$J$2,Data!D32=""),NA(),Data!D32) | J32: =IF(OR(28>$J$2,Data!D32="",Data!D31=""),NA(),ABS(Data!D32-Data!D31)) | K32: =IF(OR(28>$J$2,Data!G5<2),NA(),Data!G6) | L32: =IF(OR(28>$J$2,Data!G5<2),NA(),Data!G6+2.66*AVERAGE(J6:J104)) | M32: =IF(OR(28>$J$2,Data!G5<2),NA(),Data!G6-2.66*AVERAGE(J6:J104))
B33: 3 | C33: =Analysis!G9+B33*Analysis!G10 | D33: =IF(Analysis!G10>0,(1/(Analysis!G10*SQRT(2*PI())))*EXP(-0.5*B33^2),0) | E33: =IF(Analysis!G10>0,(1/(Analysis!G10*SQRT(2*PI())))*EXP(-0.5*((C33-Analysis!C6)/Analysis!G10)^2),0) | H33: 29 | I33: =IF(OR(29>$J$2,Data!D33=""),NA(),Data!D33) | J33: =IF(OR(29>$J$2,Data!D33="",Data!D32=""),NA(),ABS(Data!D33-Data!D32)) | K33: =IF(OR(29>$J$2,Data!G5<2),NA(),Data!G6) | L33: =IF(OR(29>$J$2,Data!G5<2),NA(),Data!G6+2.66*AVERAGE(J6:J104)) | M33: =IF(OR(29>$J$2,Data!G5<2),NA(),Data!G6-2.66*AVERAGE(J6:J104))
B34: 3.25 | C34: =Analysis!G9+B34*Analysis!G10 | D34: =IF(Analysis!G10>0,(1/(Analysis!G10*SQRT(2*PI())))*EXP(-0.5*B34^2),0) | E34: =IF(Analysis!G10>0,(1/(Analysis!G10*SQRT(2*PI())))*EXP(-0.5*((C34-Analysis!C6)/Analysis!G10)^2),0) | H34: 30 | I34: =IF(OR(30>$J$2,Data!D34=""),NA(),Data!D34) | J34: =IF(OR(30>$J$2,Data!D34="",Data!D33=""),NA(),ABS(Data!D34-Data!D33)) | K34: =IF(OR(30>$J$2,Data!G5<2),NA(),Data!G6) | L34: =IF(OR(30>$J$2,Data!G5<2),NA(),Data!G6+2.66*AVERAGE(J6:J104)) | M34: =IF(OR(30>$J$2,Data!G5<2),NA(),Data!G6-2.66*AVERAGE(J6:J104))
B35: 3.5 | C35: =Analysis!G9+B35*Analysis!G10 | D35: =IF(Analysis!G10>0,(1/(Analysis!G10*SQRT(2*PI())))*EXP(-0.5*B35^2),0) | E35: =IF(Analysis!G10>0,(1/(Analysis!G10*SQRT(2*PI())))*EXP(-0.5*((C35-Analysis!C6)/Analysis!G10)^2),0) | H35: 31 | I35: =IF(OR(31>$J$2,Data!D35=""),NA(),Data!D35) | J35: =IF(OR(31>$J$2,Data!D35="",Data!D34=""),NA(),ABS(Data!D35-Data!D34)) | K35: =IF(OR(31>$J$2,Data!G5<2),NA(),Data!G6) | L35: =IF(OR(31>$J$2,Data!G5<2),NA(),Data!G6+2.66*AVERAGE(J6:J104)) | M35: =IF(OR(31>$J$2,Data!G5<2),NA(),Data!G6-2.66*AVERAGE(J6:J104))
B36: 3.75 | C36: =Analysis!G9+B36*Analysis!G10 | D36: =IF(Analysis!G10>0,(1/(Analysis!G10*SQRT(2*PI())))*EXP(-0.5*B36^2),0) | E36: =IF(Analysis!G10>0,(1/(Analysis!G10*SQRT(2*PI())))*EXP(-0.5*((C36-Analysis!C6)/Analysis!G10)^2),0) | H36: 32 | I36: =IF(OR(32>$J$2,Data!D36=""),NA(),Data!D36) | J36: =IF(OR(32>$J$2,Data!D36="",Data!D35=""),NA(),ABS(Data!D36-Data!D35)) | K36: =IF(OR(32>$J$2,Data!G5<2),NA(),Data!G6) | L36: =IF(OR(32>$J$2,Data!G5<2),NA(),Data!G6+2.66*AVERAGE(J6:J104)) | M36: =IF(OR(32>$J$2,Data!G5<2),NA(),Data!G6-2.66*AVERAGE(J6:J104))
B37: 4 | C37: =Analysis!G9+B37*Analysis!G10 | D37: =IF(Analysis!G10>0,(1/(Analysis!G10*SQRT(2*PI())))*EXP(-0.5*B37^2),0) | E37: =IF(Analysis!G10>0,(1/(Analysis!G10*SQRT(2*PI())))*EXP(-0.5*((C37-Analysis!C6)/Analysis!G10)^2),0) | H37: 33 | I37: =IF(OR(33>$J$2,Data!D37=""),NA(),Data!D37) | J37: =IF(OR(33>$J$2,Data!D37="",Data!D36=""),NA(),ABS(Data!D37-Data!D36)) | K37: =IF(OR(33>$J$2,Data!G5<2),NA(),Data!G6) | L37: =IF(OR(33>$J$2,Data!G5<2),NA(),Data!G6+2.66*AVERAGE(J6:J104)) | M37: =IF(OR(33>$J$2,Data!G5<2),NA(),Data!G6-2.66*AVERAGE(J6:J104))
H38: 34 | I38: =IF(OR(34>$J$2,Data!D38=""),NA(),Data!D38) | J38: =IF(OR(34>$J$2,Data!D38="",Data!D37=""),NA(),ABS(Data!D38-Data!D37)) | K38: =IF(OR(34>$J$2,Data!G5<2),NA(),Data!G6) | L38: =IF(OR(34>$J$2,Data!G5<2),NA(),Data!G6+2.66*AVERAGE(J6:J104)) | M38: =IF(OR(34>$J$2,Data!G5<2),NA(),Data!G6-2.66*AVERAGE(J6:J104))
H39: 35 | I39: =IF(OR(35>$J$2,Data!D39=""),NA(),Data!D39) | J39: =IF(OR(35>$J$2,Data!D39="",Data!D38=""),NA(),ABS(Data!D39-Data!D38)) | K39: =IF(OR(35>$J$2,Data!G5<2),NA(),Data!G6) | L39: =IF(OR(35>$J$2,Data!G5<2),NA(),Data!G6+2.66*AVERAGE(J6:J104)) | M39: =IF(OR(35>$J$2,Data!G5<2),NA(),Data!G6-2.66*AVERAGE(J6:J104))
B40: Capability Index Comparison | H40: 36 | I40: =IF(OR(36>$J$2,Data!D40=""),NA(),Data!D40) | J40: =IF(OR(36>$J$2,Data!D40="",Data!D39=""),NA(),ABS(Data!D40-Data!D39)) | K40: =IF(OR(36>$J$2,Data!G5<2),NA(),Data!G6) | L40: =IF(OR(36>$J$2,Data!G5<2),NA(),Data!G6+2.66*AVERAGE(J6:J104)) | M40: =IF(OR(36>$J$2,Data!G5<2),NA(),Data!G6-2.66*AVERAGE(J6:J104))
...

Sheet History
B1: Analysis History Log
B2: Row 4 is auto-linked to the current Analysis. To save a run, copy-paste Row 4 as VALUES into the next empty row.
B3: Date | C3: Name | D3: Mode | E3: Tₘ | F3: LSL | G3: USL | H3: x̄ | I3: σ | J3: n | K3: Cp | L3: Cpk | M3: PPM Total | N3: Shift (Δ) | O3: Verdict
B4: =TODAY() | C4: =Analysis!C5 | D4: =Analysis!C10 | E4: =Analysis!C6 | F4: =Analysis!C7 | G4: =Analysis!C8 | H4: =Analysis!G9 | I4: =Analysis!G10 | J4: =Analysis!G11 | K4: =Analysis!G17 | L4: =Analysis!G18 | M4: =Analysis!J10 | N4: =Analysis!G19 | O4: =Analysis!B28

Sheet Reference
B1: Reference Guide — Formulas, Definitions & How to Use
B4: How to Use This Workbook
B5: 1. Enter specifications (Tₘ, LSL, USL) in the Analysis sheet (blue cells)
B6: 2. Choose Mode: 'Enter Manually' or 'Use Data Worksheet' (dropdown in C10)
B7: 3. If Manual: enter x̄, σ, n directly in the Analysis sheet
B8: 4. If Worksheet: enter part data in the Data sheet — mean & σ auto-link
B9: 5. All results, probability, hypothesis test, and verdict update INSTANTLY
B10: 6. View charts in the Charts sheet (bell curve + capability bars)
B11: 7. To save a run: go to History sheet, copy Row 4, paste as VALUES into Row 5+
B13: Core Capability Formulas
B14: Cp = (USL − LSL) / 6σ — Potential capability if process is perfectly centered
B15: Cpk = min[(USL − x̄) / 3σ, (x̄ − LSL) / 3σ] — Actual capability with centering error
... B52: 🔵 Blue cells = Input cells (enter your data here)
